Workbook

Sheet portada
B2: Análisis estadístico de siniestros viales · Ciudad de Buenos Aires 2019–2025
B3: Proyecto de portafolio · Data Analyst · Estadística descriptiva aplicada a política pública de seguridad vial
B4: Autor: Jeisson Marin Uribe Luis · Cliente simulado: Agencia Nacional de Seguridad Vial (ANSV)
B6: Hoja | C6: Contenido
B7: diccionario | C7: Descripción de cada variable del dataset original y de las variables derivadas.
B8: log_limpieza | C8: Cada problema detectado en los datos y la decisión tomada, con registros afectados.
B9: clasificacion_variables | C9: Clasificación estadística: cuantitativa/cualitativa, subtipo, escala y justificación.
B10: base_agregada | C10: Base de trabajo: tablas de conteo por año, mes, día, hora, vía, modo, comuna y gravedad.
B11: freq_franja_horaria | C11: Tabla de frecuencias (absoluta, relativa, acumulada) por franja horaria.
B12: freq_modo | C12: Tabla de frecuencias por modo de desplazamiento de la víctima, con Pareto.
B13: freq_tipo_via | C13: Tabla de frecuencias por tipo de vía y letalidad asociada.
B14: freq_gravedad | C14: Tabla de frecuencias por gravedad del siniestro.
B15: freq_victimas | C15: Tabla de frecuencias de la variable cuantitativa discreta “víctimas por siniestro”.
B16: estadisticas_descriptivas | C16: Tendencia central, dispersión, cuartiles y asimetría, con interpretación escrita.
B17: cruce_dia_franja | C17: Tabla cruzada día de la semana × franja horaria.
... B24: Nota: | C24: El archivo original (12 MB, 65.818 filas) se procesó completo; este libro contiene la base agregada y todas las tablas del análisis.

Sheet diccionario
A1: Diccionario de variables
A2: Dataset original “siniestros_viales_hechos.csv” (separador «;») y variables derivadas para el análisis.
A4: Variable | B4: Tipo | C4: Descripción | D4: Ejemplo | E4: Valores únicos | F4: ¿Tiene nulos?
A5: id_siniestro | B5: Texto | C5: Identificador único del siniestro | D5: LC-2019-0000053 | E5: 65.818 | F5: No
A6: numero_total_de_victimas | B6: Numérico | C6: Personas involucradas como víctimas en el siniestro | D6: 1 | E6: 1 a 26 | F6: Sí: 3.276 con “SD”
A7: numero_victimas_leve/grave/mortal_siniestro | B7: Numérico | C7: Víctimas del siniestro según gravedad | D7: 1 / 0 / 0 | E7: 0 a 26 | F7: Sí
A8: fecha_siniestro | B8: Fecha | C8: Fecha del hecho | D8: 2019-01-01 | E8: 2.557 días | F8: No
A9: anio_siniestro / mes_siniestro / dia_siniestro | B9: Numérico | C9: Componentes de la fecha | D9: 2019 / 1 / 1 | E9: 7 / 12 / 31 | F9: No
A10: hora_siniestro | B10: Hora (texto) | C10: Hora del hecho en formato HH:MM:SS | D10: 01:55:00 | E10: 0 a 23 | F10: Sí: 81
A11: rango_horario | B11: Numérico | C11: Hora redondeada provista por la fuente | D11: 1 | E11: 0 a 23 | F11: Sí
A12: direccion_normalizada_siniestro | B12: Texto | C12: Dirección del hecho | D12: ALBARELLOS AV. 2316 | E12: — | F12: Sí: 12.900
A13: comuna_siniestro | B13: Texto | C13: Comuna de la CABA donde ocurrió | D13: Comuna 8 / 12 / SD | E13: 15 + SD | F13: Sí: 3.552
A14: tipo_de_via_siniestro | B14: Texto | C14: Tipo de vía: avenida, calle, autopista, Av. Gral. Paz | D14: AVENIDA | E14: 4 + SD | F14: Sí: 12.542
A15: longitud/latitud_siniestro | B15: Numérico | C15: Coordenadas del hecho | D15: -58,44 / -34,67 | E15: — | F15: Sí (#¡REF!)
... A19: gravedad_siniestro | B19: Texto | C19: Gravedad máxima del siniestro | D19: LEVE / GRAVE / MORTAL | E19: 3 | F19: No
A20: — DERIVADAS —
A21: franja_horaria | B21: Texto (ordinal) | C21: Madrugada 0-5, Mañana 6-11, Tarde 12-17, Noche 18-23 | D21: Tarde | E21: 4 + No informado | F21: No
A22: dia_semana | B22: Texto (ordinal) | C22: Día de la semana calculado con la fecha | D22: Viernes | E22: 7 | F22: No
A23: mes_nombre / trimestre | B23: Texto / Numérico | C23: Mes y trimestre del siniestro | D23: Octubre / 4 | E23: 12 / 4 | F23: No
A24: letalidad | B24: Numérico | C24: Muertes cada 1.000 siniestros del grupo | D24: 11,7 | E24: — | F24: No

Sheet log_limpieza
A1: Log de limpieza
A2: Cada decisión tomada sobre los datos originales, con el número de registros afectados. Nada se imputó en silencio.
A4: Fecha | B4: Columna | C4: Problema encontrado | D4: Decisión tomada | E4: Registros afectados
A5: 2026-09-18 | B5: id_siniestro | C5: Verificación de duplicados exactos por identificador | D5: No se encontraron duplicados: 65.818 IDs únicos | E5: 0
A6: 2026-09-18 | B6: numero_total_de_victimas | C6: Valor “SD” (sin dato) en el total de víctimas, sobre todo en 2025 | D6: Se recalculó como leves + graves + mortales; si el resultado daba 0 se asignó 1 (hay al menos una víctima registrada) | E6: 3276
A7: 2026-09-18 | B7: hora_siniestro | C7: Hora vacía o fuera del rango 0-23 | D7: Se creó la categoría “No informado” en lugar de eliminar el registro | E7: 81
A8: 2026-09-18 | B8: comuna_siniestro | C8: Dos formatos conviviendo: “Comuna 8” y “8” | D8: Se unificó a “Comuna N” extrayendo el número | E8: 11217
A9: 2026-09-18 | B9: comuna_siniestro | C9: Valores “SD” o “#¡REF!” | D9: Se categorizó como “No informado”; no se eliminan filas porque el resto de las variables es válido | E9: 3552
A10: 2026-09-18 | B10: tipo_de_via_siniestro | C10: Valores “SD” y variantes de mayúsculas | D10: Se normalizó a Avenida, Calle, Autopista y Av. Gral. Paz; “SD” pasó a “No informado” | E10: 12542
A11: 2026-09-18 | B11: modo_desplazamiento_victima | C11: Valores “SD” y “#¡REF!” | D11: Se categorizó como “No informado” y se excluye de los porcentajes por modo | E11: 10929
A12: 2026-09-18 | B12: contraparte_siniestro | C12: Mismo valor en mayúsculas y minúsculas (“auto” / “AUTO”) | D12: Se normalizó la capitalización con NOMPROPIO(ESPACIOS()) | E12: 149
A13: 2026-09-18 | B13: contraparte_siniestro | C13: Valores “SD” o vacíos | D13: Se categorizó como “No informado” | E13: 14067
A14: 2026-09-18 | B14: fecha_siniestro | C14: Formato inconsistente: “2019-01-01” y “2025-10-1” | D14: Se estandarizó a AAAA-MM-DD; todas las fechas quedaron dentro del período 01/01/2019 – 31/12/2025 | E14: 65818
A15: 2026-09-18 | B15: geocodificación / lat / long | C15: Valores “#¡REF!” y “POINT (SD SD)” | D15: No se usan en este análisis (el alcance excluye mapas); se dejan como están | E15: —
A17: Resumen: 65.818 filas leídas · 65.818 conservadas (100 %) · 0 eliminadas. Ningún registro se descartó: los faltantes se tratan como categoría “No informado”.

Sheet clasificacion_variables
A1: Clasificación estadística de las variables
A2: Tipo, subtipo y escala de medición de cada variable usada en el análisis.
A4: Variable | B4: Tipo | C4: Subtipo | D4: Escala | E4: Justificación
A5: numero_total_de_victimas | B5: Cuantitativa | C5: Discreta | D5: Razón | E5: Son conteos enteros de personas; el cero significa ausencia real de víctimas, por eso admite razones (2 víctimas es el doble que 1).
A6: hora_siniestro | B6: Cuantitativa | C6: Discreta | D6: Intervalo | E6: Número entero de 0 a 23; el 0 es la medianoche, no la ausencia de tiempo, por lo que no tiene cero absoluto.
A7: anio_siniestro | B7: Cuantitativa | C7: Discreta | D7: Intervalo | E7: Solo toma valores enteros y el “año 0” no representa ausencia de tiempo.
A8: franja_horaria | B8: Cualitativa | C8: Ordinal | D8: Ordinal | E8: Las franjas tienen un orden natural: Madrugada < Mañana < Tarde < Noche.
A9: dia_semana | B9: Cualitativa | C9: Ordinal | D9: Ordinal | E9: Los días siguen un orden convencional cíclico (lunes a domingo).
A10: mes_siniestro | B10: Cualitativa | C10: Ordinal | D10: Ordinal | E10: Orden natural de enero a diciembre; se analiza como categoría, no como número.
A11: gravedad_siniestro | B11: Cualitativa | C11: Ordinal | D11: Ordinal | E11: Existe una jerarquía clara de impacto: Leve < Grave < Mortal.
A12: comuna_siniestro | B12: Cualitativa | C12: Nominal | D12: Nominal | E12: Unidades geográficas sin orden inherente; el número de comuna es una etiqueta.
A13: tipo_de_via_siniestro | B13: Cualitativa | C13: Nominal | D13: Nominal | E13: Categorías de infraestructura vial sin jerarquía natural.
A14: modo_desplazamiento_victima | B14: Cualitativa | C14: Nominal | D14: Nominal | E14: Formas de desplazamiento sin orden; se comparan por frecuencia, no por magnitud.
A15: contraparte_siniestro | B15: Cualitativa | C15: Nominal | D15: Nominal | E15: Con qué colisionó la víctima; categorías sin orden.
A16: letalidad (derivada) | B16: Cuantitativa | C16: Continua | D16: Razón | E16: Tasa por cada 1.000 siniestros; admite decimales y el cero significa ausencia de muertes.
A19: Advertencia metodológica: no tiene sentido calcular la media de una variable cualitativa ordinal como “franja horaria” o “gravedad”; en esos casos la medida de tendencia central válida es la moda (y la mediana en las ordinales).

Sheet base_agregada
A1: Base agregada de trabajo
A2: Conteos obtenidos del dataset completo (65.818 siniestros). Todas las tablas de frecuencias y estadísticas de este libro se calculan con fórmulas sobre estos bloques.
A4: B1 · Por año | H4: B4 · Por hora del día | N4: B6 · Por tipo de vía | T4: B9 · Por gravedad | Z4: B12 · Serie mensual
A5: Año | B5: Siniestros | C5: Víctimas | D5: Leves | E5: Graves | F5: Mortales | H5: Hora | I5: Siniestros | J5: Víctimas | K5: Mortales | N5: Tipo de vía | O5: Siniestros | P5: Víctimas | Q5: Mortales | T5: Gravedad | U5: Siniestros | V5: Víctimas | Z5: Año-Mes | AA5: Siniestros | AB5: Víctimas
A6: 2019 | B6: 10155 | C6: 11886 | D6: 11328 | E6: 454 | F6: 104 | H6: 0 | I6: 1901 | J6: 2154 | K6: 21 | N6: Avenida | O6: 30525 | P6: 34747 | Q6: 426 | T6: Leve | U6: 62174 | V6: 70854 | Z6: 2019-01 | AA6: 750 | AB6: 882
A7: 2020 | B7: 6061 | C7: 6936 | D7: 6684 | E7: 170 | F7: 82 | H7: 1 | I7: 947 | J7: 1144 | K7: 17 | N7: Calle | O7: 18794 | P7: 21039 | Q7: 150 | T7: Grave | U7: 2955 | V7: 3572 | Z7: 2019-02 | AA7: 801 | AB7: 941
A8: 2021 | B8: 7818 | C8: 9053 | D8: 8590 | E8: 367 | F8: 96 | H8: 2 | I8: 693 | J8: 806 | K8: 13 | N8: No informado | O8: 12542 | P8: 14556 | Q8: 0 | T8: Mortal | U8: 689 | V8: 767 | Z8: 2019-03 | AA8: 960 | AB8: 1151
A9: 2022 | B9: 9536 | C9: 10647 | D9: 9978 | E9: 558 | F9: 111 | H9: 3 | I9: 508 | J9: 637 | K9: 30 | N9: Av. Gral. Paz | O9: 2916 | P9: 3569 | Q9: 56 | Z9: 2019-04 | AA9: 967 | AB9: 1135
A10: 2023 | B10: 9927 | C10: 11075 | D10: 10601 | E10: 368 | F10: 106 | H10: 4 | I10: 454 | J10: 577 | K10: 25 | N10: Autopista | O10: 1041 | P10: 1282 | Q10: 71 | T10: B10 · Víctimas por siniestro | Z10: 2019-05 | AA10: 1049 | AB10: 1244
A11: 2024 | B11: 10569 | C11: 12481 | D11: 11814 | E11: 554 | F11: 113 | H11: 5 | I11: 754 | J11: 938 | K11: 32 | T11: Víctimas | U11: Siniestros | Z11: 2019-06 | AA11: 896 | AB11: 1059
A12: 2025 | B12: 11752 | C12: 13115 | D12: 12313 | E12: 711 | F12: 91 | H12: 6 | I12: 1317 | J12: 1589 | K12: 34 | N12: B7 · Por modo de desplazamiento de la víctima | T12: 1 | U12: 59052 | Z12: 2019-07 | AA12: 937 | AB12: 1176
H13: 7 | I13: 2150 | J13: 2562 | K13: 46 | N13: Modo | O13: Siniestros | P13: Víctimas | Q13: Mortales | T13: 2 | U13: 5295 | Z13: 2019-08 | AA13: 912 | AB13: 1049
A14: B2 · Por mes (acumulado 2019-2025) | H14: 8 | I14: 2960 | J14: 3485 | K14: 28 | N14: Moto | O14: 24555 | P14: 26885 | Q14: 288 | T14: 3 | U14: 911 | Z14: 2019-09 | AA14: 895 | AB14: 1067
A15: Mes | B15: Siniestros | C15: Víctimas | D15: Mortales | H15: 9 | I15: 3141 | J15: 3591 | K15: 29 | N15: No informado | O15: 10929 | P15: 12428 | Q15: 0 | T15: 4 | U15: 304 | Z15: 2019-10 | AA15: 891 | AB15: 1048
A16: Enero | B16: 4627 | C16: 5333 | D16: 63 | H16: 10 | I16: 3134 | J16: 3479 | K16: 32 | N16: Peatón | O16: 9415 | P16: 10097 | Q16: 273 | T16: 5 | U16: 134 | Z16: 2019-11 | AA16: 555 | AB16: 572
A17: Febrero | B17: 4701 | C17: 5351 | D17: 56 | H17: 11 | I17: 3384 | J17: 3848 | K17: 33 | N17: Bicicleta | O17: 7091 | P17: 7299 | Q17: 54 | T17: 6 | U17: 61 | Z17: 2019-12 | AA17: 542 | AB17: 562
A18: Marzo | B18: 5652 | C18: 6505 | D18: 53 | H18: 12 | I18: 4116 | J18: 4662 | K18: 43 | N18: Auto | O18: 7073 | P18: 9399 | Q18: 60 | T18: 7 | U18: 23 | Z18: 2020-01 | AA18: 679 | AB18: 775
A19: Abril | B19: 5263 | C19: 5982 | D19: 61 | H19: 13 | I19: 4181 | J19: 4758 | K19: 25 | N19: Transporte público | O19: 3633 | P19: 4695 | Q19: 6 | T19: 8 | U19: 19 | Z19: 2020-02 | AA19: 728 | AB19: 803
A20: Mayo | B20: 5325 | C20: 6061 | D20: 67 | H20: 14 | I20: 4458 | J20: 5022 | K20: 43 | N20: Taxi | O20: 810 | P20: 1071 | Q20: 1 | T20: 9 | U20: 3 | Z20: 2020-03 | AA20: 493 | AB20: 555
A21: Junio | B21: 5366 | C21: 6092 | D21: 56 | H21: 15 | I21: 4361 | J21: 4944 | K21: 25 | N21: Utilitario | O21: 697 | P21: 958 | Q21: 8 | T21: 10 o más | U21: 16 | Z21: 2020-04 | AA21: 194 | AB21: 214
A22: Julio | B22: 5528 | C22: 6345 | D22: 53 | H22: 16 | I22: 4610 | J22: 5208 | K22: 31 | N22: Móvil | O22: 531 | P22: 681 | Q22: 3 | Z22: 2020-05 | AA22: 328 | AB22: 369
A23: Agosto | B23: 5793 | C23: 6510 | D23: 64 | H23: 17 | I23: 4748 | J23: 5365 | K23: 33 | N23: Mixto | O23: 498 | P23: 975 | Q23: 4 | Z23: 2020-06 | AA23: 325 | AB23: 358
A24: Septiembre | B24: 5683 | C24: 6415 | D24: 55 | H24: 18 | I24: 4421 | J24: 5000 | K24: 31 | N24: Camión | O24: 250 | P24: 334 | Q24: 5 | T24: B11 · Por contraparte | Z24: 2020-07 | AA24: 359 | AB24: 387
A25: Octubre | B25: 6192 | C25: 7182 | D25: 47 | H25: 19 | I25: 3719 | J25: 4161 | K25: 37 | N25: Monopatín | O25: 207 | P25: 214 | Q25: 1 | T25: Contraparte | U25: Siniestros | V25: Víctimas | W25: Mortales | Z25: 2020-08 | AA25: 442 | AB25: 488
A26: Noviembre | B26: 5690 | C26: 6462 | D26: 55 | H26: 20 | I26: 3231 | J26: 3679 | K26: 29 | N26: Otro | O26: 129 | P26: 157 | Q26: 0 | T26: Auto | U26: 29996 | V26: 33872 | W26: 203 | Z26: 2020-09 | AA26: 497 | AB26: 547
A27: Diciembre | B27: 5998 | C27: 6955 | D27: 73 | H27: 21 | I27: 2708 | J27: 3072 | K27: 20 | T27: No informado | U27: 14067 | V27: 15831 | W27: 10 | Z27: 2020-10 | AA27: 585 | AB27: 739
H28: 22 | I28: 2224 | J28: 2542 | K28: 18 | T28: Transporte público | U28: 6035 | V28: 7283 | W28: 145 | Z28: 2020-11 | AA28: 690 | AB28: 799
H29: 23 | I29: 1617 | J29: 1874 | K29: 27 | N29: B8 · Por comuna | T29: Utilitario | U29: 3575 | V29: 4047 | W29: 35 | Z29: 2020-12 | AA29: 741 | AB29: 902
A30: B3 · Por día de la semana | H30: No informado | I30: 81 | J30: 96 | K30: 1 | N30: Comuna | O30: Siniestros | P30: Víctimas | Q30: Mortales | T30: Moto | U30: 3496 | V30: 4084 | W30: 52 | Z30: 2021-01 | AA30: 534 | AB30: 601
A31: Día | B31: Siniestros | C31: Víctimas | D31: Mortales | N31: Comuna 1 | O31: 7241 | P31: 8128 | Q31: 75 | T31: Taxi | U31: 2624 | V31: 2891 | W31: 7 | Z31: 2021-02 | AA31: 484 | AB31: 571
A32: Lunes | B32: 9670 | C32: 11050 | D32: 96 | N32: Comuna 15 | O32: 5214 | P32: 5841 | Q32: 45 | T32: Camión | U32: 2579 | V32: 2978 | W32: 125 | Z32: 2021-03 | AA32: 719 | AB32: 817
A33: Martes | B33: 10319 | C33: 11692 | D33: 107 | H33: B5 · Por franja horaria | N33: Comuna 3 | O33: 4858 | P33: 5413 | Q33: 43 | T33: Objeto fijo | U33: 1521 | V33: 1823 | W33: 87 | Z33: 2021-04 | AA33: 609 | AB33: 701
A34: Miércoles | B34: 10391 | C34: 11641 | D34: 90 | H34: Franja | I34: Siniestros | J34: Víctimas | K34: Mortales | N34: Comuna 4 | O34: 4562 | P34: 5418 | Q34: 75 | T34: Móvil | U34: 804 | V34: 977 | W34: 7 | Z34: 2021-05 | AA34: 301 | AB34: 302
A35: Jueves | B35: 10678 | C35: 12081 | D35: 124 | H35: Madrugada (0-5 hs) | I35: 5257 | J35: 6256 | K35: 138 | N35: Comuna 14 | O35: 4496 | P35: 5080 | Q35: 42 | T35: Bicicleta | U35: 390 | V35: 423 | W35: 6 | Z35: 2021-06 | AA35: 674 | AB35: 756
A36: Viernes | B36: 11120 | C36: 12560 | D36: 97 | H36: Mañana (6-11 hs) | I36: 16086 | J36: 18554 | K36: 202 | N36: Comuna 9 | O36: 4450 | P36: 5335 | Q36: 56 | T36: Múltiple | U36: 347 | V36: 524 | W36: 13 | Z36: 2021-07 | AA36: 701 | AB36: 810
A37: Sábado | B37: 7791 | C37: 9038 | D37: 107 | H37: Tarde (12-17 hs) | I37: 26474 | J37: 29959 | K37: 200 | N37: Comuna 7 | O37: 4368 | P37: 5033 | Q37: 55 | T37: Otro | U37: 204 | V37: 254 | W37: 2 | Z37: 2021-08 | AA37: 807 | AB37: 912
A38: Domingo | B38: 5849 | C38: 7131 | D38: 82 | H38: Noche (18-23 hs) | I38: 17920 | J38: 20328 | K38: 162 | N38: Comuna 12 | O38: 4310 | P38: 4983 | Q38: 43 | T38: Camioneta | U38: 74 | V38: 88 | W38: 0 | Z38: 2021-09 | AA38: 661 | AB38: 766
H39: No informado | I39: 81 | J39: 96 | K39: 1 | N39: Comuna 13 | O39: 3965 | P39: 4421 | Q39: 45 | T39: Monopatín | U39: 57 | V39: 60 | W39: 1 | Z39: 2021-10 | AA39: 833 | AB39: 992
N40: Comuna 10 | O40: 3776 | P40: 4332 | Q40: 53 | T40: Peatón | U40: 36 | V40: 44 | W40: 0 | Z40: 2021-11 | AA40: 660 | AB40: 779
N41: No informado | O41: 3552 | P41: 3981 | Q41: 0 | T41: Tren | U41: 13 | V41: 14 | W41: 10 | Z41: 2021-12 | AA41: 835 | AB41: 1046
...

Sheet freq_franja_horaria
A1: Tabla de frecuencias · Franja horaria
A2: Variable cualitativa ordinal. Responde la pregunta 1: ¿en qué momentos ocurren más siniestros?
A4: Categoría | B4: Frec. absoluta | C4: Frec. relativa | D4: Frec. rel. % | E4: Frec. acumulada | F4: Frec. ac. % | G4: Víctimas | H4: Víctimas / siniestro | I4: Mortales | J4: Muertes cada 1.000 siniestros
A5: Madrugada (0-5 hs) | B5: =base_agregada!I35 -> 5257 | C5: =B5/$B$10 -> 0.079871768 | D5: =C5 -> 0.079871768 | E5: =B5 -> 5257 | F5: =E5/$B$10 -> 0.079871768 | G5: =base_agregada!J35 -> 6256 | H5: =IF(B5=0,0,G5/B5) -> 1.1900323 | I5: =base_agregada!K35 -> 138 | J5: =IF(B5=0,0,I5/B5*1000) -> 26.250713
A6: Mañana (6-11 hs) | B6: =base_agregada!I36 -> 16086 | C6: =B6/$B$10 -> 0.24440123 | D6: =C6 -> 0.24440123 | E6: =E5+B6 -> 21343 | F6: =E6/$B$10 -> 0.324273 | G6: =base_agregada!J36 -> 18554 | H6: =IF(B6=0,0,G6/B6) -> 1.1534253 | I6: =base_agregada!K36 -> 202 | J6: =IF(B6=0,0,I6/B6*1000) -> 12.557503
A7: Tarde (12-17 hs) | B7: =base_agregada!I37 -> 26474 | C7: =B7/$B$10 -> 0.40223039 | D7: =C7 -> 0.40223039 | E7: =E6+B7 -> 47817 | F7: =E7/$B$10 -> 0.72650339 | G7: =base_agregada!J37 -> 29959 | H7: =IF(B7=0,0,G7/B7) -> 1.1316386 | I7: =base_agregada!K37 -> 200 | J7: =IF(B7=0,0,I7/B7*1000) -> 7.5545819
A8: Noche (18-23 hs) | B8: =base_agregada!I38 -> 17920 | C8: =B8/$B$10 -> 0.27226595 | D8: =C8 -> 0.27226595 | E8: =E7+B8 -> 65737 | F8: =E8/$B$10 -> 0.99876933 | G8: =base_agregada!J38 -> 20328 | H8: =IF(B8=0,0,G8/B8) -> 1.134375 | I8: =base_agregada!K38 -> 162 | J8: =IF(B8=0,0,I8/B8*1000) -> 9.0401786
A9: No informado | B9: =base_agregada!I39 -> 81 | C9: =B9/$B$10 -> 0.0012306664 | D9: =C9 -> 0.0012306664 | E9: =E8+B9 -> 65818 | F9: =E9/$B$10 -> 1 | G9: =base_agregada!J39 -> 96 | H9: =IF(B9=0,0,G9/B9) -> 1.1851852 | I9: =base_agregada!K39 -> 1 | J9: =IF(B9=0,0,I9/B9*1000) -> 12.345679
A10: TOTAL | B10: =SUM(B5:B9) -> 65818 | C10: =SUM(C5:C9) -> 1 | D10: =SUM(D5:D9) -> 1 | G10: =SUM(G5:G9) -> 75193 | I10: =SUM(I5:I9) -> 703
A11: Control: la suma de frecuencias relativas debe ser 1,0000
A13: Lectura: la franja con más siniestros es la Tarde (12-17 hs) con el 40,2 % del total; sin embargo, la Madrugada (0-5 hs), con apenas el 8,0 % de los casos, tiene la mayor letalidad: 26,3 muertes cada 1.000 siniestros, 3,5 veces la de la tarde.

Sheet freq_modo
A1: Tabla de frecuencias · Modo de desplazamiento de la víctima
A2: Variable cualitativa nominal, ordenada de mayor a menor. Responde la pregunta 2: ¿qué usuarios concentran los siniestros y las víctimas?
A4: Modo de desplazamiento | B4: Frec. absoluta | C4: Frec. relativa | D4: Frec. rel. % | E4: Frec. acumulada | F4: Frec. ac. % | G4: Víctimas | H4: Víctimas / siniestro | I4: Mortales | J4: Muertes cada 1.000 siniestros
A5: Moto | B5: =base_agregada!O14 -> 24555 | C5: =B5/$B$18 -> 0.37307424 | D5: =C5 -> 0.37307424 | E5: =B5 -> 24555 | F5: =E5/$B$18 -> 0.37307424 | G5: =base_agregada!P14 -> 26885 | H5: =IF(B5=0,0,G5/B5) -> 1.094889 | I5: =base_agregada!Q14 -> 288 | J5: =IF(B5=0,0,I5/B5*1000) -> 11.728772
A6: No informado | B6: =base_agregada!O15 -> 10929 | C6: =B6/$B$18 -> 0.1660488 | D6: =C6 -> 0.1660488 | E6: =E5+B6 -> 35484 | F6: =E6/$B$18 -> 0.53912304 | G6: =base_agregada!P15 -> 12428 | H6: =IF(B6=0,0,G6/B6) -> 1.137158 | I6: =base_agregada!Q15 -> 0 | J6: =IF(B6=0,0,I6/B6*1000) -> 0
A7: Peatón | B7: =base_agregada!O16 -> 9415 | C7: =B7/$B$18 -> 0.14304598 | D7: =C7 -> 0.14304598 | E7: =E6+B7 -> 44899 | F7: =E7/$B$18 -> 0.68216901 | G7: =base_agregada!P16 -> 10097 | H7: =IF(B7=0,0,G7/B7) -> 1.0724376 | I7: =base_agregada!Q16 -> 273 | J7: =IF(B7=0,0,I7/B7*1000) -> 28.996283
A8: Bicicleta | B8: =base_agregada!O17 -> 7091 | C8: =B8/$B$18 -> 0.10773649 | D8: =C8 -> 0.10773649 | E8: =E7+B8 -> 51990 | F8: =E8/$B$18 -> 0.7899055 | G8: =base_agregada!P17 -> 7299 | H8: =IF(B8=0,0,G8/B8) -> 1.029333 | I8: =base_agregada!Q17 -> 54 | J8: =IF(B8=0,0,I8/B8*1000) -> 7.615287
A9: Auto | B9: =base_agregada!O18 -> 7073 | C9: =B9/$B$18 -> 0.107463 | D9: =C9 -> 0.107463 | E9: =E8+B9 -> 59063 | F9: =E9/$B$18 -> 0.8973685 | G9: =base_agregada!P18 -> 9399 | H9: =IF(B9=0,0,G9/B9) -> 1.3288562 | I9: =base_agregada!Q18 -> 60 | J9: =IF(B9=0,0,I9/B9*1000) -> 8.4829634
A10: Transporte público | B10: =base_agregada!O19 -> 3633 | C10: =B10/$B$18 -> 0.055197666 | D10: =C10 -> 0.055197666 | E10: =E9+B10 -> 62696 | F10: =E10/$B$18 -> 0.95256617 | G10: =base_agregada!P19 -> 4695 | H10: =IF(B10=0,0,G10/B10) -> 1.2923204 | I10: =base_agregada!Q19 -> 6 | J10: =IF(B10=0,0,I10/B10*1000) -> 1.6515277
A11: Taxi | B11: =base_agregada!O20 -> 810 | C11: =B11/$B$18 -> 0.012306664 | D11: =C11 -> 0.012306664 | E11: =E10+B11 -> 63506 | F11: =E11/$B$18 -> 0.96487283 | G11: =base_agregada!P20 -> 1071 | H11: =IF(B11=0,0,G11/B11) -> 1.3222222 | I11: =base_agregada!Q20 -> 1 | J11: =IF(B11=0,0,I11/B11*1000) -> 1.2345679
A12: Utilitario | B12: =base_agregada!O21 -> 697 | C12: =B12/$B$18 -> 0.010589808 | D12: =C12 -> 0.010589808 | E12: =E11+B12 -> 64203 | F12: =E12/$B$18 -> 0.97546264 | G12: =base_agregada!P21 -> 958 | H12: =IF(B12=0,0,G12/B12) -> 1.374462 | I12: =base_agregada!Q21 -> 8 | J12: =IF(B12=0,0,I12/B12*1000) -> 11.477762
A13: Móvil | B13: =base_agregada!O22 -> 531 | C13: =B13/$B$18 -> 0.0080677018 | D13: =C13 -> 0.0080677018 | E13: =E12+B13 -> 64734 | F13: =E13/$B$18 -> 0.98353034 | G13: =base_agregada!P22 -> 681 | H13: =IF(B13=0,0,G13/B13) -> 1.2824859 | I13: =base_agregada!Q22 -> 3 | J13: =IF(B13=0,0,I13/B13*1000) -> 5.6497175
A14: Mixto | B14: =base_agregada!O23 -> 498 | C14: =B14/$B$18 -> 0.0075663192 | D14: =C14 -> 0.0075663192 | E14: =E13+B14 -> 65232 | F14: =E14/$B$18 -> 0.99109666 | G14: =base_agregada!P23 -> 975 | H14: =IF(B14=0,0,G14/B14) -> 1.9578313 | I14: =base_agregada!Q23 -> 4 | J14: =IF(B14=0,0,I14/B14*1000) -> 8.0321285
A15: Camión | B15: =base_agregada!O24 -> 250 | C15: =B15/$B$18 -> 0.003798353 | D15: =C15 -> 0.003798353 | E15: =E14+B15 -> 65482 | F15: =E15/$B$18 -> 0.99489501 | G15: =base_agregada!P24 -> 334 | H15: =IF(B15=0,0,G15/B15) -> 1.336 | I15: =base_agregada!Q24 -> 5 | J15: =IF(B15=0,0,I15/B15*1000) -> 20
A16: Monopatín | B16: =base_agregada!O25 -> 207 | C16: =B16/$B$18 -> 0.0031450363 | D16: =C16 -> 0.0031450363 | E16: =E15+B16 -> 65689 | F16: =E16/$B$18 -> 0.99804005 | G16: =base_agregada!P25 -> 214 | H16: =IF(B16=0,0,G16/B16) -> 1.0338164 | I16: =base_agregada!Q25 -> 1 | J16: =IF(B16=0,0,I16/B16*1000) -> 4.8309179
A17: Otro | B17: =base_agregada!O26 -> 129 | C17: =B17/$B$18 -> 0.0019599502 | D17: =C17 -> 0.0019599502 | E17: =E16+B17 -> 65818 | F17: =E17/$B$18 -> 1 | G17: =base_agregada!P26 -> 157 | H17: =IF(B17=0,0,G17/B17) -> 1.2170543 | I17: =base_agregada!Q26 -> 0 | J17: =IF(B17=0,0,I17/B17*1000) -> 0
A18: TOTAL | B18: =SUM(B5:B17) -> 65818 | C18: =SUM(C5:C17) -> 1 | D18: =SUM(D5:D17) -> 1 | G18: =SUM(G5:G17) -> 75193 | I18: =SUM(I5:I17) -> 703
A19: Control: la suma de frecuencias relativas debe ser 1,0000
A21: Pareto: moto, peatón y bicicleta reúnen el 62,4 % de los siniestros y el 87,5 % de las víctimas mortales. La categoría “No informado” (16,6 %) corresponde en su mayoría a registros de 2025 sin completar y no tiene muertes asignadas.

Sheet freq_tipo_via
A1: Tabla de frecuencias · Tipo de vía
A2: Variable cualitativa nominal. Responde la segunda parte de la pregunta 2: ¿qué vías concentran las víctimas?
A4: Tipo de vía | B4: Frec. absoluta | C4: Frec. relativa | D4: Frec. rel. % | E4: Frec. acumulada | F4: Frec. ac. % | G4: Víctimas | H4: Víctimas / siniestro | I4: Mortales | J4: Muertes cada 1.000 siniestros
A5: Avenida | B5: =base_agregada!O6 -> 30525 | C5: =B5/$B$10 -> 0.46377891 | D5: =C5 -> 0.46377891 | E5: =B5 -> 30525 | F5: =E5/$B$10 -> 0.46377891 | G5: =base_agregada!P6 -> 34747 | H5: =IF(B5=0,0,G5/B5) -> 1.1383129 | I5: =base_agregada!Q6 -> 426 | J5: =IF(B5=0,0,I5/B5*1000) -> 13.955774
A6: Calle | B6: =base_agregada!O7 -> 18794 | C6: =B6/$B$10 -> 0.28554499 | D6: =C6 -> 0.28554499 | E6: =E5+B6 -> 49319 | F6: =E6/$B$10 -> 0.74932389 | G6: =base_agregada!P7 -> 21039 | H6: =IF(B6=0,0,G6/B6) -> 1.119453 | I6: =base_agregada!Q7 -> 150 | J6: =IF(B6=0,0,I6/B6*1000) -> 7.9812706
A7: No informado | B7: =base_agregada!O8 -> 12542 | C7: =B7/$B$10 -> 0.19055578 | D7: =C7 -> 0.19055578 | E7: =E6+B7 -> 61861 | F7: =E7/$B$10 -> 0.93987967 | G7: =base_agregada!P8 -> 14556 | H7: =IF(B7=0,0,G7/B7) -> 1.1605804 | I7: =base_agregada!Q8 -> 0 | J7: =IF(B7=0,0,I7/B7*1000) -> 0
A8: Av. Gral. Paz | B8: =base_agregada!O9 -> 2916 | C8: =B8/$B$10 -> 0.04430399 | D8: =C8 -> 0.04430399 | E8: =E7+B8 -> 64777 | F8: =E8/$B$10 -> 0.98418366 | G8: =base_agregada!P9 -> 3569 | H8: =IF(B8=0,0,G8/B8) -> 1.2239369 | I8: =base_agregada!Q9 -> 56 | J8: =IF(B8=0,0,I8/B8*1000) -> 19.20439
A9: Autopista | B9: =base_agregada!O10 -> 1041 | C9: =B9/$B$10 -> 0.015816342 | D9: =C9 -> 0.015816342 | E9: =E8+B9 -> 65818 | F9: =E9/$B$10 -> 1 | G9: =base_agregada!P10 -> 1282 | H9: =IF(B9=0,0,G9/B9) -> 1.2315082 | I9: =base_agregada!Q10 -> 71 | J9: =IF(B9=0,0,I9/B9*1000) -> 68.20365
A10: TOTAL | B10: =SUM(B5:B9) -> 65818 | C10: =SUM(C5:C9) -> 1 | D10: =SUM(D5:D9) -> 1 | G10: =SUM(G5:G9) -> 75193 | I10: =SUM(I5:I9) -> 703
A11: Control: la suma de frecuencias relativas debe ser 1,0000
A13: Lectura: las avenidas concentran el 46,4 % de los siniestros y el 60,6 % de las muertes. Las autopistas, con solo el 1,6 % de los hechos, presentan la letalidad más alta: 68,2 muertes cada 1.000 siniestros, 8,5 veces la de las calles.

Sheet freq_gravedad
A1: Tabla de frecuencias · Gravedad del siniestro
A2: Variable cualitativa ordinal (Leve < Grave < Mortal).
A4: Gravedad | B4: Frec. absoluta | C4: Frec. relativa | D4: Frec. rel. % | E4: Frec. acumulada | F4: Frec. ac. % | G4: Víctimas | H4: Víctimas / siniestro
A5: Leve | B5: =base_agregada!U6 -> 62174 | C5: =B5/$B$8 -> 0.94463521 | D5: =C5 -> 0.94463521 | E5: =B5 -> 62174 | F5: =E5/$B$8 -> 0.94463521 | G5: =base_agregada!V6 -> 70854 | H5: =IF(B5=0,0,G5/B5) -> 1.1396082
A6: Grave | B6: =base_agregada!U7 -> 2955 | C6: =B6/$B$8 -> 0.044896533 | D6: =C6 -> 0.044896533 | E6: =E5+B6 -> 65129 | F6: =E6/$B$8 -> 0.98953174 | G6: =base_agregada!V7 -> 3572 | H6: =IF(B6=0,0,G6/B6) -> 1.2087986
A7: Mortal | B7: =base_agregada!U8 -> 689 | C7: =B7/$B$8 -> 0.010468261 | D7: =C7 -> 0.010468261 | E7: =E6+B7 -> 65818 | F7: =E7/$B$8 -> 1 | G7: =base_agregada!V8 -> 767 | H7: =IF(B7=0,0,G7/B7) -> 1.1132075
A8: TOTAL | B8: =SUM(B5:B7) -> 65818 | C8: =SUM(C5:C7) -> 1 | D8: =SUM(D5:D7) -> 1 | G8: =SUM(G5:G7) -> 75193
A9: Control: la suma de frecuencias relativas debe ser 1,0000
A11: Lectura: el 94,5 % de los siniestros registrados es leve, el 4,5 % grave y el 1,0 % mortal. Aun así, ese 1 % equivale a 703 personas fallecidas en siete años.

Sheet freq_victimas
A1: Tabla de frecuencias · Víctimas por siniestro
A2: Variable cuantitativa discreta. Como toma pocos valores, se tabula valor por valor y se agrupa la cola en “10 o más”.
A4: Víctimas por siniestro | B4: Valor (para cálculos) | C4: Frec. absoluta | D4: Frec. relativa | E4: Frec. rel. % | F4: Frec. acumulada | G4: Frec. ac. %
A5: 1 | B5: 1 | C5: =base_agregada!U12 -> 59052 | D5: =C5/$C$15 -> 0.89720137 | E5: =D5 -> 0.89720137 | F5: =C5 -> 59052 | G5: =F5/$C$15 -> 0.89720137
A6: 2 | B6: 2 | C6: =base_agregada!U13 -> 5295 | D6: =C6/$C$15 -> 0.080449117 | E6: =D6 -> 0.080449117 | F6: =F5+C6 -> 64347 | G6: =F6/$C$15 -> 0.97765049
A7: 3 | B7: 3 | C7: =base_agregada!U14 -> 911 | D7: =C7/$C$15 -> 0.013841198 | E7: =D7 -> 0.013841198 | F7: =F6+C7 -> 65258 | G7: =F7/$C$15 -> 0.99149169
A8: 4 | B8: 4 | C8: =base_agregada!U15 -> 304 | D8: =C8/$C$15 -> 0.0046187973 | E8: =D8 -> 0.0046187973 | F8: =F7+C8 -> 65562 | G8: =F8/$C$15 -> 0.99611049
A9: 5 | B9: 5 | C9: =base_agregada!U16 -> 134 | D9: =C9/$C$15 -> 0.0020359172 | E9: =D9 -> 0.0020359172 | F9: =F8+C9 -> 65696 | G9: =F9/$C$15 -> 0.9981464
A10: 6 | B10: 6 | C10: =base_agregada!U17 -> 61 | D10: =C10/$C$15 -> 0.00092679814 | E10: =D10 -> 0.00092679814 | F10: =F9+C10 -> 65757 | G10: =F10/$C$15 -> 0.9990732
A11: 7 | B11: 7 | C11: =base_agregada!U18 -> 23 | D11: =C11/$C$15 -> 0.00034944848 | E11: =D11 -> 0.00034944848 | F11: =F10+C11 -> 65780 | G11: =F11/$C$15 -> 0.99942265
A12: 8 | B12: 8 | C12: =base_agregada!U19 -> 19 | D12: =C12/$C$15 -> 0.00028867483 | E12: =D12 -> 0.00028867483 | F12: =F11+C12 -> 65799 | G12: =F12/$C$15 -> 0.99971133
A13: 9 | B13: 9 | C13: =base_agregada!U20 -> 3 | D13: =C13/$C$15 -> 4.5580236e-05 | E13: =D13 -> 4.5580236e-05 | F13: =F12+C13 -> 65802 | G13: =F13/$C$15 -> 0.99975691
A14: 10 o más | B14: 10 | C14: =base_agregada!U21 -> 16 | D14: =C14/$C$15 -> 0.00024309459 | E14: =D14 -> 0.00024309459 | F14: =F13+C14 -> 65818 | G14: =F14/$C$15 -> 1
A15: TOTAL | C15: =SUM(C5:C14) -> 65818 | D15: =SUM(D5:D14) -> 1 | E15: =SUM(E5:E14) -> 1
A17: Interpretación: el 89,7 % de los siniestros involucra una sola víctima. Los siniestros con 3 o más víctimas son apenas el 2,2 % (1.471 casos), pero son los que generan los eventos de mayor impacto: el máximo registrado es de 26 víctimas en un solo hecho.
A18: Nota de cálculo: la categoría “10 o más” (16 siniestros) se computa como 10 en las medidas de dispersión; el efecto sobre el desvío estándar es menor a 0,01.

Sheet estadisticas_descriptivas
A1: Estadísticas descriptivas
A2: Variable: número de víctimas por siniestro (cuantitativa discreta). Calculadas con fórmulas sobre la tabla de frecuencias.
A4: Medida | B4: Fórmula utilizada | C4: Resultado | D4: Interpretación
A5: Cantidad de siniestros (n) | B5: SUMA(frecuencias) | C5: =SUM(freq_victimas!C5:C14) -> 65818 | D5: Base del análisis: 65.818 siniestros con al menos una víctima.
A6: Total de víctimas (10+ computado como 10) | B6: SUMAPRODUCTO(valores;frecuencias) | C6: =SUMPRODUCT(freq_victimas!B5:B14,freq_victimas!C5:C14) -> 75127 | D6: 75.127 con la cola agrupada; el total exacto del dataset es 75.193 víctimas.
A7: Media aritmética | B7: Total víctimas / n | C7: =C6/C5 -> 1.1414355 | D7: En promedio, cada siniestro involucra 1,14 víctimas.
A8: Mediana | B8: valor donde la frec. acumulada alcanza n/2 | C8: =INDEX(freq_victimas!B5:B14,COUNTIF(freq_victimas!F5:F14,"<"&C5/2)+1) -> 1 | D8: La mitad de los siniestros tiene 1 víctima o menos: la distribución está muy concentrada.
A9: Moda | B9: valor con mayor frecuencia | C9: =INDEX(freq_victimas!B5:B14,MATCH(MAX(freq_victimas!C5:C14),freq_victimas!C5:C14,0)) -> 1 | D9: El número de víctimas más frecuente es 1 (59.052 siniestros).
A10: Mínimo | B10: MIN(valores observados) | C10: =1 -> 1 | D10: Todo siniestro registrado en esta base tiene al menos una víctima.
A11: Máximo | B11: MAX(valores observados) | C11: =26 -> 26 | D11: El siniestro más grave del período involucró 26 víctimas.
A12: Rango | B12: Máximo - Mínimo | C12: =C11-C10 -> 25 | D12: Amplitud total de la variable.
A13: Varianza muestral | B13: SUMAPRODUCTO(frec;(valor-media)^2)/(n-1) | C13: =SUMPRODUCT(freq_victimas!C5:C14,(freq_victimas!B5:B14-C7)^2)/(C5-1) -> 0.26246072 | D13: Dispersión cuadrática respecto de la media.
A14: Desvío estándar | B14: RAIZ(varianza) | C14: =SQRT(C13) -> 0.5123092 | D14: Las víctimas por siniestro varían en promedio ±0,51 respecto de la media.
A15: Coeficiente de variación | B15: Desvío / Media × 100 | C15: =C14/C7*100 -> 44.882888 | D15: 44,6 %: dispersión moderada. La mayoría de los siniestros se parece entre sí en número de víctimas.
A16: Primer cuartil Q1 | B16: valor donde la frec. ac. alcanza 25 % | C16: =INDEX(freq_victimas!B5:B14,COUNTIF(freq_victimas!F5:F14,"<"&C5*0.25)+1) -> 1 | D16: El 25 % de los siniestros tiene 1 víctima o menos.
A17: Tercer cuartil Q3 | B17: valor donde la frec. ac. alcanza 75 % | C17: =INDEX(freq_victimas!B5:B14,COUNTIF(freq_victimas!F5:F14,"<"&C5*0.75)+1) -> 1 | D17: El 75 % de los siniestros tiene 1 víctima o menos.
A18: Rango intercuartílico (RIC) | B18: Q3 - Q1 | C18: =C17-C16 -> 0 | D18: RIC = 0: el 50 % central de los datos se concentra en un único valor.
A19: Asimetría (media − mediana) | B19: Media - Mediana | C19: =C7-C8 -> 0.14143547 | D19: Media > mediana: distribución asimétrica positiva, con cola hacia la derecha.
A22: Conclusión estadística
A23: La distribución de víctimas por siniestro es fuertemente asimétrica positiva: media 1,14 frente a mediana 1, con el 89,7 % de los casos en un único valor. En términos de política pública esto significa que el problema no son los eventos multitudinarios sino la altísima frecuencia de siniestros individuales: 65.818 hechos en siete años, unos 26 por día.
A28: Medida — hora del siniestro | B28: Resultado | C28: Interpretación
A29: Media de la hora | B29: =SUMPRODUCT(base_agregada!H6:H29,base_agregada!I6:I29)/SUM(base_agregada!I6:I29) -> 13.642271 | C29: La “hora central” de los siniestros es alrededor de las 13 hs.
A30: Hora modal (mayor frecuencia) | B30: =INDEX(base_agregada!H6:H29,MATCH(MAX(base_agregada!I6:I29),base_agregada!I6:I29,0)) -> 17 | C30: La hora con más siniestros es las 17 hs (4.748 casos).
A31: Hora con menos siniestros | B31: =INDEX(base_agregada!H6:H29,MATCH(MIN(base_agregada!I6:I29),base_agregada!I6:I29,0)) -> 4 | C31: La hora más tranquila son las 4 de la madrugada (454 casos).
A32: Desvío estándar de la hora | B32: =SQRT(SUMPRODUCT(base_agregada!I6:I29,(base_agregada!H6:H29-SUMPRODUCT(base_agregada!H6:H29,base_agregada!I6:I29)/SUM(base_agregada!I6:I29))^2)/(SUM(base_agregada!I6:I29)-1)) -> 5.5426775 | C32: Los siniestros se reparten a lo largo del día con una dispersión de ±5,7 horas.

Sheet cruce_dia_franja
A1: Tabla cruzada · Día de la semana × franja horaria
A2: Equivalente a una tabla dinámica: conteo de siniestros. La franja “Madrugada y mañana” agrupa 0-11 hs.
A4: Franja horaria | B4: Lunes | C4: Martes | D4: Miércoles | E4: Jueves | F4: Viernes | G4: Sábado | H4: Domingo | I4: Total | J4: % del total
A5: Madrugada y mañana (0-11 hs) | B5: 3302 | C5: 3265 | D5: 3169 | E5: 3306 | F5: 3390 | G5: 2635 | H5: 2276 | I5: =SUM(B5:H5) -> 21343 | J5: =I5/$I$8 -> 0.324273
A6: Tarde (12-17 hs) | B6: 3967 | C6: 4420 | D6: 4444 | E6: 4467 | F6: 4672 | G6: 2801 | H6: 1703 | I6: =SUM(B6:H6) -> 26474 | J6: =I6/$I$8 -> 0.40223039
A7: Noche (18-23 hs) | B7: 2401 | C7: 2634 | D7: 2778 | E7: 2905 | F7: 3058 | G7: 2355 | H7: 1870 | I7: =SUM(B7:H7) -> 18001 | J7: =I7/$I$8 -> 0.27349661
A8: Total | B8: =SUM(B5:B7) -> 9670 | C8: =SUM(C5:C7) -> 10319 | D8: =SUM(D5:D7) -> 10391 | E8: =SUM(E5:E7) -> 10678 | F8: =SUM(F5:F7) -> 11120 | G8: =SUM(G5:G7) -> 7791 | H8: =SUM(H5:H7) -> 5849 | I8: =SUM(I5:I7) -> 65818
A9: % del total semanal | B9: =B8/$I$8 -> 0.1469203 | C9: =C8/$I$8 -> 0.15678082 | D9: =D8/$I$8 -> 0.15787475 | E9: =E8/$I$8 -> 0.16223525 | F9: =F8/$I$8 -> 0.16895074 | G9: =G8/$I$8 -> 0.11837187 | H9: =H8/$I$8 -> 0.088866268
A11: Celda de mayor riesgo: viernes por la tarde, con 4.672 siniestros (7,1 % de todo el período). Los cinco días hábiles en la franja de la tarde concentran el 33,4 % de los siniestros.
A12: El domingo es el día con menos siniestros (8,9 %), pero su letalidad es de 14,0 muertes cada 1.000, contra 8,7 del viernes.

Sheet analisis_temporal
A1: Análisis temporal
A2: Serie anual y mensual. Responde la pregunta 3: ¿la situación mejora, empeora o está estable?
A4: Año | B4: Siniestros | C4: Variación % anual | D4: Víctimas | E4: Víctimas mortales | F4: Var. % mortales | G4: Letalidad (muertes/1.000)
A5: 2019 | B5: =base_agregada!B6 -> 10155 | D5: =base_agregada!C6 -> 11886 | E5: =base_agregada!F6 -> 104 | G5: =E5/B5*1000 -> 10.24126
A6: 2020 | B6: =base_agregada!B7 -> 6061 | C6: =B6/B5-1 -> -0.40315116 | D6: =base_agregada!C7 -> 6936 | E6: =base_agregada!F7 -> 82 | F6: =E6/E5-1 -> -0.21153846 | G6: =E6/B6*1000 -> 13.529121
A7: 2021 | B7: =base_agregada!B8 -> 7818 | C7: =B7/B6-1 -> 0.28988616 | D7: =base_agregada!C8 -> 9053 | E7: =base_agregada!F8 -> 96 | F7: =E7/E6-1 -> 0.17073171 | G7: =E7/B7*1000 -> 12.279355
A8: 2022 | B8: =base_agregada!B9 -> 9536 | C8: =B8/B7-1 -> 0.2197493 | D8: =base_agregada!C9 -> 10647 | E8: =base_agregada!F9 -> 111 | F8: =E8/E7-1 -> 0.15625 | G8: =E8/B8*1000 -> 11.640101
A9: 2023 | B9: =base_agregada!B10 -> 9927 | C9: =B9/B8-1 -> 0.041002517 | D9: =base_agregada!C10 -> 11075 | E9: =base_agregada!F10 -> 106 | F9: =E9/E8-1 -> -0.045045045 | G9: =E9/B9*1000 -> 10.677949
A10: 2024 | B10: =base_agregada!B11 -> 10569 | C10: =B10/B9-1 -> 0.064672106 | D10: =base_agregada!C11 -> 12481 | E10: =base_agregada!F11 -> 113 | F10: =E10/E9-1 -> 0.066037736 | G10: =E10/B10*1000 -> 10.691645
A11: 2025 | B11: =base_agregada!B12 -> 11752 | C11: =B11/B10-1 -> 0.11193112 | D11: =base_agregada!C12 -> 13115 | E11: =base_agregada!F12 -> 91 | F11: =E11/E10-1 -> -0.19469027 | G11: =E11/B11*1000 -> 7.7433628
A12: Total | B12: =SUM(B5:B11) -> 65818 | D12: =SUM(D5:D11) -> 75193 | E12: =SUM(E5:E11) -> 703 | G12: =E12/B12*1000 -> 10.680969
A15: Indicador de tendencia | B15: Valor | C15: Lectura
A16: Pendiente de la recta (siniestros/año) | B16: =SLOPE(B5:B11,A5:A11) -> 568.42857 | C16: Cada año se suman en promedio 568 siniestros más.
A17: Ordenada al origen | B17: =INTERCEPT(B5:B11,A5:A11) -> -1139960
A18: R² de la tendencia lineal | B18: =RSQ(B5:B11,A5:A11) -> 0.42244007 | C18: 0,42: la tendencia lineal explica menos de la mitad de la variación, por el corte del ASPO 2020.
A19: Variación 2019 → 2025 (siniestros) | B19: =B11/B5-1 -> 0.15726243 | C19: Los siniestros crecieron un 15,7 % respecto de 2019.
A20: Variación 2021 → 2025 (post-pandemia) | B20: =B11/B7-1 -> 0.50319775 | C20: Desde la salida de la pandemia el crecimiento es del 50,3 %.
A21: Variación 2019 → 2025 (muertes) | B21: =E11/E5-1 -> -0.125 | C21: Las víctimas mortales bajaron un 12,5 %.
A22: R² de la tendencia de muertes | B22: =RSQ(E5:E11,A5:A11) -> 0.05105964 | C22: 0,05: no hay tendencia lineal en las muertes; el indicador es estable con oscilaciones.
A24: Respuesta a la pregunta 3: la situación empeora en frecuencia y mejora en gravedad. Hay más siniestros que nunca en el período (11.752 en 2025, el máximo de la serie), pero las muertes son las segundas más bajas (91) y la letalidad cayó de 10,2 a 7,7 muertes cada 1.000 siniestros.
A27: Mes | B27: Siniestros | C27: % del total | D27: Víctimas | E27: Mortales
A28: Enero | B28: =base_agregada!B16 -> 4627 | C28: =B28/SUM($B$28:$B$39) -> 0.070299918 | D28: =base_agregada!C16 -> 5333 | E28: =base_agregada!D16 -> 63
A29: Febrero | B29: =base_agregada!B17 -> 4701 | C29: =B29/SUM($B$28:$B$39) -> 0.07142423 | D29: =base_agregada!C17 -> 5351 | E29: =base_agregada!D17 -> 56
A30: Marzo | B30: =base_agregada!B18 -> 5652 | C30: =B30/SUM($B$28:$B$39) -> 0.085873165 | D30: =base_agregada!C18 -> 6505 | E30: =base_agregada!D18 -> 53
A31: Abril | B31: =base_agregada!B19 -> 5263 | C31: =B31/SUM($B$28:$B$39) -> 0.079962928 | D31: =base_agregada!C19 -> 5982 | E31: =base_agregada!D19 -> 61
A32: Mayo | B32: =base_agregada!B20 -> 5325 | C32: =B32/SUM($B$28:$B$39) -> 0.08090492 | D32: =base_agregada!C20 -> 6061 | E32: =base_agregada!D20 -> 67
A33: Junio | B33: =base_agregada!B21 -> 5366 | C33: =B33/SUM($B$28:$B$39) -> 0.08152785 | D33: =base_agregada!C21 -> 6092 | E33: =base_agregada!D21 -> 56
A34: Julio | B34: =base_agregada!B22 -> 5528 | C34: =B34/SUM($B$28:$B$39) -> 0.083989182 | D34: =base_agregada!C22 -> 6345 | E34: =base_agregada!D22 -> 53
A35: Agosto | B35: =base_agregada!B23 -> 5793 | C35: =B35/SUM($B$28:$B$39) -> 0.088015437 | D35: =base_agregada!C23 -> 6510 | E35: =base_agregada!D23 -> 64
A36: Septiembre | B36: =base_agregada!B24 -> 5683 | C36: =B36/SUM($B$28:$B$39) -> 0.086344161 | D36: =base_agregada!C24 -> 6415 | E36: =base_agregada!D24 -> 55
A37: Octubre | B37: =base_agregada!B25 -> 6192 | C37: =B37/SUM($B$28:$B$39) -> 0.094077608 | D37: =base_agregada!C25 -> 7182 | E37: =base_agregada!D25 -> 47
A38: Noviembre | B38: =base_agregada!B26 -> 5690 | C38: =B38/SUM($B$28:$B$39) -> 0.086450515 | D38: =base_agregada!C26 -> 6462 | E38: =base_agregada!D26 -> 55
A39: Diciembre | B39: =base_agregada!B27 -> 5998 | C39: =B39/SUM($B$28:$B$39) -> 0.091130086 | D39: =base_agregada!C27 -> 6955 | E39: =base_agregada!D27 -> 73
A41: Estacionalidad: octubre (9,4 %) y diciembre (9,1 %) son los meses con más siniestros; enero y febrero los que menos (7,0 % y 7,1 %), coherente con el receso estival y la menor circulación en la Ciudad. Diciembre concentra además el mayor número de muertes (73).

Sheet hallazgos
A1: Los 5 hallazgos principales
A2: Tabla síntesis que alimenta el informe y la presentación ejecutiva.
A4: # | B4: Pregunta de negocio | C4: Hallazgo cuantificado | D4: Evidencia estadística
A5: 1 | B5: ¿Cuándo ocurren más siniestros? | C5: La tarde (12-17 hs) concentra el 40,2 % de los siniestros y el viernes es el día más crítico (16,9 %). La celda de mayor riesgo es viernes por la tarde: 4.672 hechos, el 7,1 % del total. | D5: Tabla cruzada día × franja horaria; tabla de frecuencias por franja.
A7: 2 | B7: ¿Cuándo son más graves? | C7: La madrugada (0-5 hs) reúne solo el 8,0 % de los siniestros pero 26,3 muertes cada 1.000, frente a 7,6 en la tarde: 3,5 veces más letal. | D7: Frecuencias por franja cruzadas con gravedad.
A9: 3 | B9: ¿Qué usuarios concentran las víctimas? | C9: Los usuarios vulnerables —moto, peatón y bicicleta— son el 62,4 % de los siniestros y el 87,5 % de las muertes. Las motos solas explican el 37,3 % de los hechos y el 41,0 % de los fallecidos; los peatones tienen la mayor letalidad (29,0 cada 1.000). | D9: Tabla de frecuencias por modo de desplazamiento y letalidad.
A11: 4 | B11: ¿Qué vías concentran el riesgo? | C11: Las avenidas concentran el 46,4 % de los siniestros y el 60,6 % de las muertes. Las autopistas, con el 1,6 % de los hechos, tienen la letalidad más alta: 68,2 muertes cada 1.000, 8,5 veces la de las calles. | D11: Tabla de frecuencias por tipo de vía.
A13: 5 | B13: ¿La situación mejora o empeora? | C13: Empeora en frecuencia y mejora en gravedad: los siniestros crecieron 15,7 % entre 2019 y 2025 (+50,3 % desde 2021) mientras las muertes bajaron 12,5 % y la letalidad pasó de 10,2 a 7,7 cada 1.000. | D13: Serie anual 2019-2025 con tendencia lineal (pendiente +568/año, R²=0,42).

Sheet graficos
A1: Gráficos estadísticos
A2: Cada gráfico se eligió según el tipo de variable: barras para cualitativas, histograma para la cuantitativa discreta, líneas para la serie temporal y torta para la gravedad.
A68: Gráficos adicionales del informe (generados a partir de las mismas tablas):
